[2024-08-13T19:16:13.116+0000] {taskinstance.py:1159} INFO - Dependencies all met for dep_context=non-requeueable deps ti=<TaskInstance: etl_reddit_pipeline.s3_upload manual__2024-08-13T19:16:06.661485+00:00 [queued]>
[2024-08-13T19:16:13.130+0000] {taskinstance.py:1159} INFO - Dependencies all met for dep_context=requeueable deps ti=<TaskInstance: etl_reddit_pipeline.s3_upload manual__2024-08-13T19:16:06.661485+00:00 [queued]>
[2024-08-13T19:16:13.130+0000] {taskinstance.py:1361} INFO - Starting attempt 1 of 1
[2024-08-13T19:16:13.149+0000] {taskinstance.py:1382} INFO - Executing <Task(PythonOperator): s3_upload> on 2024-08-13 19:16:06.661485+00:00
[2024-08-13T19:16:13.155+0000] {standard_task_runner.py:57} INFO - Started process 106 to run task
[2024-08-13T19:16:13.159+0000] {standard_task_runner.py:84} INFO - Running: ['airflow', 'tasks', 'run', 'etl_reddit_pipeline', 's3_upload', 'manual__2024-08-13T19:16:06.661485+00:00', '--job-id', '20', '--raw', '--subdir', 'DAGS_FOLDER/reddit_dag.py', '--cfg-path', '/tmp/tmp2wq992o3']
[2024-08-13T19:16:13.162+0000] {standard_task_runner.py:85} INFO - Job 20: Subtask s3_upload
[2024-08-13T19:16:13.215+0000] {task_command.py:416} INFO - Running <TaskInstance: etl_reddit_pipeline.s3_upload manual__2024-08-13T19:16:06.661485+00:00 [running]> on host fdf0cefe5923
[2024-08-13T19:16:13.314+0000] {taskinstance.py:1662} INFO - Exporting env vars: AIRFLOW_CTX_DAG_OWNER='Seif Yasser' AIRFLOW_CTX_DAG_ID='etl_reddit_pipeline' AIRFLOW_CTX_TASK_ID='s3_upload' AIRFLOW_CTX_EXECUTION_DATE='2024-08-13T19:16:06.661485+00:00' AIRFLOW_CTX_TRY_NUMBER='1' AIRFLOW_CTX_DAG_RUN_ID='manual__2024-08-13T19:16:06.661485+00:00'
[2024-08-13T19:16:13.329+0000] {logging_mixin.py:151} INFO - __init__() got an unexpected keyword argument 'SECRET'
[2024-08-13T19:16:13.333+0000] {taskinstance.py:1937} ERROR - Task failed with exception
Traceback (most recent call last):
  File "/home/airflow/.local/lib/python3.9/site-packages/airflow/operators/python.py", line 192, in execute
    return_value = self.execute_callable()
  File "/home/airflow/.local/lib/python3.9/site-packages/airflow/operators/python.py", line 209, in execute_callable
    return self.python_callable(*self.op_args, **self.op_kwargs)
  File "/opt/airflow/pipelines/aws_s3_pipeline.py", line 10, in upload_s3_pipeline
    upload_to_s3(s3, file_path, AWS_BUCKET_NAME, file_path.split('/')[-1])
  File "/opt/airflow/etls/aws_etl.py", line 29, in upload_to_s3
    s3.put(file_path, bucket + '/raw/' + s3_file_name)
  File "/home/airflow/.local/lib/python3.9/site-packages/fsspec/asyn.py", line 118, in wrapper
    return sync(self.loop, func, *args, **kwargs)
  File "/home/airflow/.local/lib/python3.9/site-packages/fsspec/asyn.py", line 103, in sync
    raise return_result
  File "/home/airflow/.local/lib/python3.9/site-packages/fsspec/asyn.py", line 56, in _runner
    result[0] = await coro
  File "/home/airflow/.local/lib/python3.9/site-packages/fsspec/asyn.py", line 536, in _put
    trailing_sep(rpath) or await self._isdir(rpath)
  File "/home/airflow/.local/lib/python3.9/site-packages/s3fs/core.py", line 1411, in _isdir
    return bool(await self._lsdir(path))
  File "/home/airflow/.local/lib/python3.9/site-packages/s3fs/core.py", line 706, in _lsdir
    async for c in self._iterdir(
  File "/home/airflow/.local/lib/python3.9/site-packages/s3fs/core.py", line 737, in _iterdir
    await self.set_session()
  File "/home/airflow/.local/lib/python3.9/site-packages/s3fs/core.py", line 502, in set_session
    self.session = aiobotocore.session.AioSession(**self.kwargs)
TypeError: __init__() got an unexpected keyword argument 'SECRET'
[2024-08-13T19:16:13.347+0000] {taskinstance.py:1400} INFO - Marking task as FAILED. dag_id=etl_reddit_pipeline, task_id=s3_upload, execution_date=20240813T191606, start_date=20240813T191613, end_date=20240813T191613
[2024-08-13T19:16:13.360+0000] {standard_task_runner.py:104} ERROR - Failed to execute job 20 for task s3_upload (__init__() got an unexpected keyword argument 'SECRET'; 106)
[2024-08-13T19:16:13.371+0000] {local_task_job_runner.py:228} INFO - Task exited with return code 1
[2024-08-13T19:16:13.390+0000] {taskinstance.py:2778} INFO - 0 downstream tasks scheduled from follow-on schedule check
